Workbook
Name q: [1]Metal!#REF!
Name REKAPBARANG: #REF!
Name REKAPBARANG: #REF!
Name REKAPMATERIAL: #REF!
Name REKAPMATERIAL: #REF!
Name tes: '[2]Costing T1'!#REF!
Name yds: [3]YDS!$A$1:$H$65536
Name yds: [3]YDS!$A$1:$H$65536
Name yds: [3]YDS!$A$1:$H$65536
Name yds: [3]YDS!$A$1:$H$65536
Name yds: [4]YDS!$A$1:$H$65536

Sheet DB_MOTOR
A2: PRICELIST MOTOR
B4: KW | C4: HP | D4: CLASS | E4: CMP | K4: ATT
E5: 2 Pole | F5: Disc 50% | G5: 4 Pole | H5: Disc 50% | I5: 6 Pole | J5: Disc 50% | K5: 2 Pole | L5: IDR | M5: 4 Pole | N5: IDR | O5: 6 Pole | P5: IDR | Q5: 8 Pole | R5: IDR
B6: 0.25 | C6: 0.35 | D6: IE1 | E6: ****** | G6: 1540008 | I6: ****** | K6: ******* | M6: ******* | O6: ******* | Q6: *******
B7: 0.37 | C7: 0.5 | E7: 1408243 | F7: =50%*E7 -> 704121.5 | G7: 1622362 | H7: =50%*G7 -> 811181 | I7: 2067070 | J7: =I7*50% -> 1033535 | K7: 67 | L7: =(K7+(1%*K7)-(5%*K7))*12299 -> 791071.68 | M7: 73 | N7: =(M7+(1%*M7)-(5%*M7))*12299 -> 861913.92 | O7: 95 | P7: =(O7+(1%*O7)-(5%*O7))*12299 -> 1121668.8 | Q7: 133 | R7: =(Q7+(1%*Q7)-(5%*Q7))*12299 -> 1570336.3
B8: 0.55 | C8: 0.75 | E8: 1589420 | F8: =50%*E8 -> 794710 | G8: 1918834 | H8: =50%*G8 -> 959417 | I8: 2330600 | J8: =I8*50% -> 1165300 | K8: 73 | L8: =(K8+(1%*K8)-(5%*K8))*12299 -> 861913.92 | M8: 97 | N8: =(M8+(1%*M8)-(5%*M8))*12299 -> 1145282.9 | O8: 106 | P8: =(O8+(1%*O8)-(5%*O8))*12299 -> 1251546.2 | Q8: 147 | R8: =(Q8+(1%*Q8)-(5%*Q8))*12299 -> 1735634.9
B9: 0.75 | C9: 1 | E9: 2034129 | F9: =50%*E9 -> 1017064.5 | G9: 2075306 | H9: =50%*G9 -> 1037653 | I9: 2610602 | J9: =I9*50% -> 1305301 | K9: 91 | L9: =(K9+(1%*K9)-(5%*K9))*12299 -> 1074440.6 | M9: 105 | N9: =(M9+(1%*M9)-(5%*M9))*12299 -> 1239739.2 | O9: 129 | P9: =(O9+(1%*O9)-(5%*O9))*12299 -> 1523108.2 | Q9: 168 | R9: =(Q9+(1%*Q9)-(5%*Q9))*12299 -> 1983582.7
B10: 1.1 | C10: 1.5 | E10: 2157658 | F10: =50%*E10 -> 1078829 | G10: 2610602 | H10: =50%*G10 -> 1305301 | I10: 3063546 | J10: =I10*50% -> 1531773 | K10: 102 | L10: =(K10+(1%*K10)-(5%*K10))*12299 -> 1204318.1 | M10: 120 | N10: =(M10+(1%*M10)-(5%*M10))*12299 -> 1416844.8 | O10: 148 | P10: =(O10+(1%*O10)-(5%*O10))*12299 -> 1747441.9 | Q10: 204 | R10: =(Q10+(1%*Q10)-(5%*Q10))*12299 -> 2408636.2
B11: 1.5 | C11: 2 | E11: 2610602 | F11: =50%*E11 -> 1305301 | G11: 3005899 | H11: =50%*G11 -> 1502949.5 | I11: 3755314 | J11: =I11*50% -> 1877657 | K11: 123 | L11: =(K11+(1%*K11)-(5%*K11))*12299 -> 1452265.9 | M11: 136 | N11: =(M11+(1%*M11)-(5%*M11))*12299 -> 1605757.4 | O11: 166 | P11: =(O11+(1%*O11)-(5%*O11))*12299 -> 1959968.6 | Q11: 251 | R11: =(Q11+(1%*Q11)-(5%*Q11))*12299 -> 2963567
B12: 2.2 | C12: 3 | E12: 3047075 | F12: =50%*E12 -> 1523537.5 | G12: 3804726 | H12: =50%*G12 -> 1902363 | I12: 5015321 | J12: =I12*50% -> 2507660.5 | K12: 141 | L12: =(K12+(1%*K12)-(5%*K12))*12299 -> 1664792.6 | M12: 170 | N12: =(M12+(1%*M12)-(5%*M12))*12299 -> 2007196.8 | O12: 216 | P12: =(O12+(1%*O12)-(5%*O12))*12299 -> 2550320.6 | Q12: 292 | R12: =(Q12+(1%*Q12)-(5%*Q12))*12299 -> 3447655.7
B13: 3 | C13: 4 | E13: 3944727 | F13: =50%*E13 -> 1972363.5 | G13: 4397670 | H13: =50%*G13 -> 2198835 | I13: 6374152 | J13: =I13*50% -> 3187076 | K13: 182 | L13: =(K13+(1%*K13)-(5%*K13))*12299 -> 2148881.3 | M13: 191 | N13: =(M13+(1%*M13)-(5%*M13))*12299 -> 2255144.6 | O13: 277 | P13: =(O13+(1%*O13)-(5%*O13))*12299 -> 3270550.1 | Q13: 326 | R13: =(Q13+(1%*Q13)-(5%*Q13))*12299 -> 3849095
B14: 4 | C14: 5.5 | E14: 4900026 | F14: =50%*E14 -> 2450013 | G14: 5624735 | H14: =50%*G14 -> 2812367.5 | I14: 7403569 | J14: =I14*50% -> 3701784.5 | K14: 216 | L14: =(K14+(1%*K14)-(5%*K14))*12299 -> 2550320.6 | M14: 245 | N14: =(M14+(1%*M14)-(5%*M14))*12299 -> 2892724.8 | O14: 322 | P14: =(O14+(1%*O14)-(5%*O14))*12299 -> 3801866.9 | Q14: 479 | R14: =(Q14+(1%*Q14)-(5%*Q14))*12299 -> 5655572.2
B15: 5.5 | C15: 7.5 | E15: 7082391 | F15: =50%*E15 -> 3541195.5 | G15: 7205920 | H15: =50%*G15 -> 3602960 | I15: 8836518 | J15: =I15*50% -> 4418259 | K15: 314 | L15: =(K15+(1%*K15)-(5%*K15))*12299 -> 3707410.6 | M15: 303 | N15: =(M15+(1%*M15)-(5%*M15))*12299 -> 3577533.1 | O15: 377 | P15: =(O15+(1%*O15)-(5%*O15))*12299 -> 4451254.1 | Q15: 527 | R15: =(Q15+(1%*Q15)-(5%*Q15))*12299 -> 6222310.1
B16: 7.5 | C16: 10 | E16: 7815336 | F16: =50%*E16 -> 3907668 | G16: 8581222 | H16: =50%*G16 -> 4290611 | I16: 12328301 | J16: =I16*50% -> 6164150.5 | K16: 339 | L16: =(K16+(1%*K16)-(5%*K16))*12299 -> 4002586.6 | M16: 362 | N16: =(M16+(1%*M16)-(5%*M16))*12299 -> 4274148.5 | O16: 512 | P16: =(O16+(1%*O16)-(5%*O16))*12299 -> 6045204.5 | Q16: 620 | R16: =(Q16+(1%*Q16)-(5%*Q16))*12299 -> 7320364.8
B17: 11 | C17: 15 | E17: 12649479 | F17: =50%*E17 -> 6324739.5 | G17: 13085952 | H17: =50%*G17 -> 6542976 | I17: 15218904 | J17: =I17*50% -> 7609452 | K17: 522 | L17: =(K17+(1%*K17)-(5%*K17))*12299 -> 6163274.9 | M17: 541 | N17: =(M17+(1%*M17)-(5%*M17))*12299 -> 6387608.6 | O17: 632 | P17: =(O17+(1%*O17)-(5%*O17))*12299 -> 7462049.3 | Q17: 837 | R17: =(Q17+(1%*Q17)-(5%*Q17))*12299 -> 9882492.5
B18: 15 | C18: 20 | E18: 13958898 | F18: =50%*E18 -> 6979449 | G18: 15433023 | H18: =50%*G18 -> 7716511.5 | I18: 19954223 | J18: =I18*50% -> 9977111.5 | K18: 578 | L18: =(K18+(1%*K18)-(5%*K18))*12299 -> 6824469.1 | M18: 645 | N18: =(M18+(1%*M18)-(5%*M18))*12299 -> 7615540.8 | O18: 856 | P18: =(O18+(1%*O18)-(5%*O18))*12299 -> 10106826 | Q18: 1081 | R18: =(Q18+(1%*Q18)-(5%*Q18))*12299 -> 12763410
B19: 18.5 | C19: 25 | E19: 16190674 | F19: =50%*E19 -> 8095337 | G19: 19740105 | H19: =50%*G19 -> 9870052.5 | I19: 24911897 | J19: =I19*50% -> 12455948 | K19: 639 | L19: =(K19+(1%*K19)-(5%*K19))*12299 -> 7544698.6 | M19: 819 | N19: =(M19+(1%*M19)-(5%*M19))*12299 -> 9669965.8 | O19: 1021 | P19: =(O19+(1%*O19)-(5%*O19))*12299 -> 12054988 | Q19: 1351 | R19: =(Q19+(1%*Q19)-(5%*Q19))*12299 -> 15951311
B20: 22 | C20: 30 | E20: 20810699 | F20: =50%*E20 -> 10405350 | G20: 21543644 | H20: =50%*G20 -> 10771822 | I20: 26756613 | J20: =I20*50% -> 13378306
B23: SELISIH CMP & ATT
B24: KW | C24: HP | D24: CLASS | E24: 2POLE | F24: (%) | G24: 4POLE | H24: (%) | I24: 6POLE | J24: (%)
B26: 0.25 | C26: 0.35 | D26: IE1
B27: 0.37 | C27: 0.5 | E27: =F7-L7 -> -86950.18 | F27: =E27/F7 -> -0.12348747 | G27: =H7-N7 -> -50732.92 | H27: =G27/H7 -> -0.062542047 | I27: =J7-P7 -> -88133.8 | J27: =I27/J7 -> -0.085274132
B28: 0.55 | C28: 0.75 | E28: =F8-L8 -> -67203.92 | F28: =E28/F8 -> -0.08456408 | G28: =H8-N8 -> -185865.88 | H28: =G28/H8 -> -0.19372794 | I28: =J8-P8 -> -86246.24 | J28: =I28/J8 -> -0.074012048
B29: 0.75 | C29: 1 | E29: =F9-L9 -> -57376.14 | F29: =E29/F9 -> -0.056413472 | G29: =H9-N9 -> -202086.2 | H29: =G29/H9 -> -0.19475316 | I29: =J9-P9 -> -217807.16 | J29: =I29/J9 -> -0.16686355
B30: 1.1 | C30: 1.5 | E30: =F10-L10 -> -125489.08 | F30: =E30/F10 -> -0.11631971 | G30: =H10-N10 -> -111543.8 | H30: =G30/H10 -> -0.085454466 | I30: =J10-P10 -> -215668.92 | J30: =I30/J10 -> -0.14079692
B31: 1.5 | C31: 2 | E31: =F11-L11 -> -146964.92 | F31: =E31/F11 -> -0.11259083 | G31: =H11-N11 -> -102807.94 | H31: =G31/H11 -> -0.068404121 | I31: =J11-P11 -> -82311.64 | J31: =I31/J11 -> -0.043837421
B32: 2.2 | C32: 3 | E32: =F12-L12 -> -141255.14 | F32: =E32/F12 -> -0.092715237 | G32: =H12-N12 -> -104833.8 | H32: =G32/H12 -> -0.055107148 | I32: =J12-P12 -> -42660.14 | J32: =I32/J12 -> -0.017011928
B33: 3 | C33: 4 | E33: =F13-L13 -> -176517.78 | F33: =E33/F13 -> -0.089495562 | G33: =H13-N13 -> -56309.64 | H33: =G33/H13 -> -0.025608852 | I33: =J13-P13 -> -83474.08 | J33: =I33/J13 -> -0.026191431
B34: 4 | C34: 5.5 | E34: =F14-L14 -> -100307.64 | F34: =E34/F14 -> -0.040941677 | G34: =H14-N14 -> -80357.3 | H34: =G34/H14 -> -0.028572831 | I34: =J14-P14 -> -100082.38 | J34: =I34/J14 -> -0.027036252
B35: 5.5 | C35: 7.5 | E35: =F15-L15 -> -166215.06 | F35: =E35/F15 -> -0.046937555 | G35: =H15-N15 -> 25426.88 | H35: =G35/H15 -> 0.0070572196 | I35: =J15-P15 -> -32995.08 | J35: =I35/J15 -> -0.0074678918
B36: 7.5 | C36: 10 | E36: =F16-L16 -> -94918.56 | F36: =E36/F16 -> -0.024290334 | G36: =H16-N16 -> 16462.52 | H36: =G36/H16 -> 0.0038368708 | I36: =J16-P16 -> 118946.02 | J36: =I36/J16 -> 0.019296417
B37: 11 | C37: 15 | E37: =F17-L17 -> 161464.62 | F37: =E37/F17 -> 0.025529055 | G37: =H17-N17 -> 155367.36 | H37: =G37/H17 -> 0.023745672 | I37: =J17-P17 -> 147402.72 | J37: =I37/J17 -> 0.019371003
B38: 15 | C38: 20 | E38: =F18-L18 -> 154979.88 | F38: =E38/F18 -> 0.022205174 | G38: =H18-N18 -> 100970.7 | H38: =G38/H18 -> 0.013085019 | I38: =J18-P18 -> -129714.74 | J38: =I38/J18 -> -0.013001232
B39: 18.5 | C39: 25 | E39: =F19-L19 -> 550638.44 | F39: =E39/F19 -> 0.068019212 | G39: =H19-N19 -> 200086.74 | H39: =G39/H19 -> 0.020272105 | I39: =J19-P19 -> 400960.66 | J39: =I39/J19 -> 0.032190295
B40: 22 | C40: 30

Sheet DB-SanMu Plug Fan
A1: xx
B2: SanMu EC Plug Fans
B3: Model | C3: Motor KW | D3: OSX(H) | E3: AHU(M) | F3: AHU(H) | G3: RTU(M) | H3: SBH(M) | I3: FOB China U/P | J3: USD
B4: ECF(K)6D280-PLHDAL1-RF | C4: 1.14 | E4: 1 | G4: 1 | H4: 1 | I4: 577.9 | J4: =I4*0.77 -> 444.983
B5: ECF(K)8D310-PLHDAL1-RF | C5: 1.65 | F5: 1 | I5: 712 | J5: =I5*0.77 -> 548.24
B6: ECF(K)8D310-PLHDAL5-RF | C6: 3.03 | F6: 1 | I6: 810.3 | J6: =I6*0.77 -> 623.931
B7: ECF(K)8D355-PLHDAL0-RF | C7: 2.56 | D7: 1 | E7: 1 | H7: 1 | I7: 911 | J7: =I7*0.77 -> 701.47
B8: ECF(K)8D355-PLHDAL11-RF | C8: 3.25 | F8: 1 | H8: 1 | I8: 1046.2 | J8: =I8*0.77 -> 805.574
B9: ECF(K)8D355-PLHDAL19A-RF | C9: 0.815 | E9: 1 | G9: 1 | H9: 1 | I9: 765 | J9: =I9*0.77 -> 589.05
B10: ECF(K)10D450-PLHDAL0-RF | C10: 5.7 | D10: 1 | F10: 1 | G10: 1 | I10: 1350 | J10: =I10*0.77 -> 1039.5
B11: ECF(K)8D500-PLHDAL7-RF | C11: 4.13 | H11: 1 | I11: 1150 | J11: =I11*0.77 -> 885.5
B12: ECF(K)8D560-PLHDAL10C-RF | C12: 4.8 | E12: 1 | G12: 1 | H12: 1 | I12: 1200 | J12: =I12*0.77 -> 924
B13: ECF(K)10D630-PLHDAL1-RF | C13: 6.85 | E13: 1 | F13: 1 | G13: 1 | H13: 1 | I13: 1950 | J13: =I13*0.77 -> 1501.5
B14: ECF(K)8D630-PLHDAL10Y-RF | C14: 3.45 | H14: 1 | I14: 1450 | J14: =I14*0.77 -> 1116.5

Sheet Master
A1: BUSH NG. | B1: List Price | F1: Motor | J1: Blower
B2: METRIC | C2: INCH | F2: Motor 0.18kW-2P | G2: 56.2 | P2: Pentapost | R2: Centerpost | T2: Cornerpiece | V2: Omega Joint | X2: Panel Clip | Z2: Tebal Panel
B3: Rupiah | C3: Rupiah | F3: Motor 0.37kW-2P | G3: 67 | O3: Type | P3: kG/m | Q3: Rp/m | R3: kG/m | S3: Rp/m | T3: kG/Pc | U3: Rp/Pc | V3: kG/Pc | W3: Rp/Pc | X3: kG/m | Y3: Rp/m | Z3: mm | AC3: Type | AD3: Cost | AE3: Irridiance
A4: Bush 1008 | B4: 160000 | C4: 320000 | F4: Motor 0.55kW-2P | G4: 73.5 | J4: TYPE | K4: Ex-work | N4: 1 | O4: 1520T(NA06) | P4: 0.316 | Q4: =0.316*75000 -> 23700 | R4: 0.336 | S4: =0.399*75000 -> 29925 | T4: 0.12 | U4: 15500 | V4: 0 | W4: 0 | X4: 0 | Y4: 0 | Z4: 15 | AC4: ESL 20W x 515mmL | AD4: 58 | AE4: 72uW/cm2
A5: Bush 1108 | B5: 180000 | C5: 360000 | F5: Motor 0.75kW-2P | G5: 89.1 | K5: (USD) | N5: 2 | O5: 1520T(NA20) | P5: 0.316 | Q5: =0.316*80000 -> 25280 | R5: 0.336 | S5: =0.336*80000 -> 26880 | T5: 0.12 | U5: 15500 | V5: 0 | W5: 0 | X5: 0 | Y5: 0 | Z5: 15 | AC5: ESL 40W x 910mmL | AD5: 59.9 | AE5: 145uW/cm2
A6: Bush 1210 | B6: 240000 | C6: 480000 | F6: Motor 1.1kW-2P | G6: 95.5 | N6: 3 | O6: 1540T(NA06) | P6: 0.832 | Q6: =0.832*75000 -> 62400 | R6: 0.539 | S6: =0.539*75000 -> 40425 | T6: 0.123886 | U6: 15500 | V6: 0 | W6: 0 | X6: 0 | Y6: 0 | Z6: 15 | AC6: ESL 60W x 550mmL | AD6: 39.8 | AE6: 165uW/cm2
A7: Bush 1215 | B7: 260000 | C7: 520000 | F7: Motor 1.5kW-2P | G7: 114.5 | N7: 4 | O7: 1540T(NA20) | P7: 0.832 | Q7: =0.832*80000 -> 66560 | R7: 0.539 | S7: =0.539*75000 -> 40425 | T7: 0.123886 | U7: 15500 | V7: 0 | W7: 0 | X7: 0 | Y7: 0 | Z7: 15 | AC7: ESL 80W x 843mmL | AD7: 40.9 | AE7: 245uW/cm2
A8: Bush 1610 | B8: 290000 | C8: 580000 | F8: Motor 2.2kW-2P | G8: 132.3 | J8: AT 07/07-S | K8: 74 | L8: 5 | N8: 5 | O8: 2540Y(NA06) | P8: 1.337 | Q8: =(0.694+0.376)*75000+12500*4 -> 130250 | R8: =0.378+0.517 -> 0.895 | S8: =(0.378+0.517)*75000+12500*4 -> 117125 | T8: 0.13427 | U8: =(1.5*2)*15000 -> 45000 | V8: 0.035 | W8: =(0.4*15000)*2 -> 12000 | X8: 0.202 | Y8: =X8*95000 -> 19190 | Z8: 25 | AC8: ESL 95W x 530mmL | AD8: 51.3 | AE8: 305uW/cm2
A9: Bush 1615 | B9: 300000 | C9: 600000 | F9: Motor 3kW-2P | G9: 167.4 | J9: AT 07/07-S C/W M/F | K9: 82 | L9: 5 | N9: 6 | O9: 2540Y(NA20) | P9: 1.337 | Q9: =(0.694+0.376)*80000+12500*4 -> 135600 | R9: 1.249 | S9: =(0.378+0.517)*80000+12500*4 -> 121600 | T9: 0.13427 | U9: =(1.5*2)*15000 -> 45000 | V9: 0.035 | W9: =(0.4*15000)*2 -> 12000 | X9: 0.202 | Y9: =X9*75000 -> 15150 | Z9: 25 | AC9: ESL 120W x 1148mmL | AD9: 53.5 | AE9: 340uW/cm2
A10: Bush 2012 | B10: 370000 | C10: 740000 | F10: Motor 4kW-2P | G10: 198.8 | J10: AT 09/07-S | K10: 54 | L10: 6.6 | N10: 7 | O10: 5060Y(NA06) | P10: 1.773 | Q10: =(1.083+0.376)*85000+12500*4 -> 174015 | R10: =0.576+0.517 -> 1.093 | S10: =(0.576+0.517)*75000+12500*4 -> 131975 | T10: 0.42476 | U10: =(2.8*2)*15000 -> 84000 | V10: 0.056628 | W10: 24000 | X10: 0.202 | Y10: =X10*75000 -> 15150 | Z10: 50 | AC10: ESL 150W x 1554mmL | AD10: 57.1 | AE10: 400uW/cm2
A11: Bush 2517 | B11: 660000 | C11: 1320000 | F11: Motor 5.5kW-2P | G11: 285.8 | J11: AT 09/07-S C/W M/F | K11: 59 | L11: 6.6 | N11: 8 | O11: 5060Y(NA20) | P11: 1.773 | Q11: =(1.083+0.376)*90000+12500*4 -> 181310 | R11: 1.428 | S11: =(0.576+0.517)*80000+12500*4 -> 137440 | T11: 0.42476 | U11: =(2.8*2)*15000 -> 84000 | V11: 0.056628 | W11: 24000 | X11: 0.202 | Y11: =X11*75000 -> 15150 | Z11: 50 | AC11: RLM 22" | AD11: =5300000/14000 -> 378.57143
A12: Bush 2525 | B12: 750000 | C12: 1500000 | F12: Motor 7.5kW-2P | G12: 338.6 | J12: AT 09/09-S | K12: 56 | L12: 7.9 | N12: 9 | O12: 5060N(NA06) | P12: 1.61207 | Q12: 126976.09 | R12: 1.2431 | S12: 95095.756 | T12: 0.21 | U12: 58597.98 | V12: 0.04 | W12: 17807.16 | X12: 0.17758621 | Y12: 11905.95 | Z12: 50 | AC12: RLM 33" | AD12: =6300000/14000 -> 450
A13: Bush 3020 | B13: 1060000 | C13: 2120000 | F13: Motor 11kW-2P | G13: 494.7 | J13: AT 09/09-S C/W M/F | K13: 62 | L13: 7.9 | M13: LB20 | N13: 10 | O13: 5060A(NA20) | P13: 1.9327586 | Q13: 183475.87 | R13: 1.5689655 | S13: 154397.74 | T13: 0.21 | U13: 58597.98 | V13: 0.04 | W13: 17807.16 | X13: 0.17758621 | Y13: 13769.49 | Z13: 50 | AC13: RLM 61" | AD13: =8500000/14000 -> 607.14286
A14: Bush 3030 | B14: 1420000 | C14: 2840000 | F14: Motor 15kW-2P | G14: 609.7 | J14: AT 10/08-S | K14: 59 | L14: 8.3 | N14: 11 | O14: 2550T(304) | P14: 4.969 | Q14: =P14*65000 -> 322985 | R14: 4.225 | S14: =R14*65000 -> 274625 | T14: 0.772 | U14: 31390 | V14: 0.062 | W14: 3719 | X14: 0 | Y14: 0 | Z14: 25
A15: Bush 3525 | B15: 1750000 | C15: 3500000 | F15: Motor 18.5kW-2P | G15: 710.1 | J15: AT 10/08-S C/W M/F | K15: 66 | L15: 8.3 | N15: 12 | O15: 2550T(316) | P15: 5.081 | Q15: =P15*80000 -> 406480 | R15: 4.317 | S15: =R15*80000 -> 345360 | T15: 0.792 | U15: 47203 | V15: 0.064 | W15: 3814 | X15: 0 | Y15: 0 | Z15: 25
A16: Bush 3535 | B16: 2290000 | C16: 4580000 | F16: Motor 22kW-2P | G16: 901.8 | J16: AT 10/10-S | K16: 65 | L16: 9.3 | N16: 13 | O16: 5070T(304) | P16: 6.147 | Q16: =P16*65000 -> 399555 | R16: 5.005 | S16: =R16*65000 -> 325325 | T16: 1.914 | U16: 77809 | V16: 0.094 | W16: 3805 | X16: 0 | Y16: 0 | Z16: 50 | AC16: DPG MagRFHelic | AD16: =675000/15000 -> 45
A17: Bush 4030 | B17: 3100000 | C17: 5600000 | F17: Motor 30kW-2P | G17: 1169.1 | J17: AT 10/10-S C/W M/F | K17: 72 | L17: 9.3 | N17: 14 | O17: 5070T(316) | P17: 6.291 | Q17: =P17*80000 -> 503280 | R17: 5.117 | S17: =R17*80000 -> 409360 | T17: 1.963 | U17: 117007 | V17: 0.096 | W17: 5722 | X17: 0 | Y17: 0 | Z17: 50 | AC17: DPG Magnehelic | AD17: =1600000/15000 -> 106.66667
A18: Bush 4040 | B18: 3700000 | C18: 6700000 | F18: Motor 37kW-2P | G18: 1379.7 | J18: AT 12/09-S | K18: 86 | L18: 12.7 | N18: 15 | O18: 2540A(304) | P18: 2.074 | Q18: 745100 | R18: 1.897 | S18: 792400 | T18: 0.31 | U18: 740100 | V18: 0.094 | W18: 176300 | X18: 0 | Y18: 0 | Z18: 25
A19: Bush 4535 | B19: 4100000 | C19: 7400000 | F19: Motor 45kW-2P | G19: 1714.5 | J19: AT 12/09-S C/W M/F | K19: 98 | L19: 12.7 | N19: 16 | O19: 2540A(316) | P19: 2.074 | Q19: 875200 | R19: 1.897 | S19: 922500 | T19: 0.31 | U19: 740100 | V19: 0.094 | W19: 176300 | X19: 0 | Y19: 0 | Z19: 25
A20: Bush 4545 | B20: 5100000 | C20: 8700000 | F20: Motor 55kW-2P | G20: 2134.7 | J20: AT 12/12-S | K20: 92 | L20: 15.2 | N20: 17 | O20: 4550A(304) | P20: 2.63 | Q20: 875200 | R20: 2.61 | S20: 863300 | T20: 0.494 | U20: 775300 | V20: 0.15 | W20: 176300 | X20: 0 | Y20: 0 | Z20: 45
A21: Bush 5040 | B21: 5800000 | C21: 8700000 | F21: Motor 75kW-2P | G21: 2780 | J21: AT 12/12-S C/W M/F | K21: 104 | L21: 15.2 | N21: 18 | O21: 4550A(316) | P21: 2.63 | Q21: 898800 | R21: 2.61 | S21: 887000 | T21: 0.494 | U21: 775300 | V21: 0.15 | W21: 176300 | X21: 0 | Y21: 0 | Z21: 45
A22: Bush 5050 | B22: 6800000 | C22: 10200000 | F22: Motor 90kW-2P | G22: 3529.5 | J22: AT 15/11-S | K22: 107 | L22: 17.7
A23: Bush 6050 | B23: 26000000 | C23: 39000000 | F23: Motor 110kW-2P | G23: 4286.6 | J23: AT 15/11-S C/W M/F | K23: 130 | L23: 17.7 | P23: T | Q23: L | R23: P | S23: M
A24: Bush 7060 | B24: 32000000 | C24: 48000000 | F24: Motor 0.18kW-4P | G24: =57.3 -> 57.3 | J24: AT 15/15-S | K24: 115 | L24: 20.6 | O24: DS 25 | P24: 2 | Q24: 185 | R24: 1000 | S24: =8000*P24*Q24*R24/1000000000 -> 2.96
A25: Pulley | C25: 48000000 | F25: Motor 0.37kW-4P | G25: =73.5 -> 73.5 | J25: AT 15/15-S C/W M/F | K25: 137 | L25: 20.6 | O25: DS 50 | P25: 2 | Q25: 273 | R25: 1000 | S25: =8000*P25*Q25*R25/1000000000 -> 4.368
F26: Motor 0.55kW-4P | G26: =85.4 -> 85.4 | J26: AT 18/13-S | K26: 150 | L26: 27
A27: Pitch Dia. | B27: Price | F27: Motor 0.75kW-4P | G27: =90.8 -> 90.8 | J27: AT 18/13-S C/W F | K27: 180 | L27: 27
F28: Motor 1.1kW-4P | G28: =107.5 -> 107.5 | J28: AT 18/18-S | K28: 166 | L28: 32.5
A29: 1SPZ50 | B29: 470000 | F29: Motor 1.5kW-4P | G29: =118.8 -> 118.8 | J29: AT 18/18-S C/W F | K29: 196 | L29: 32.5
A30: 1SPZ56 | B30: 510000 | F30: Motor 2.2kW-4P | G30: =142.6 -> 142.6 | J30: AT 22/22-S | K30: 430 | L30: 82.5
A31: 1SPZ60 | B31: 570000 | F31: Motor 3kW-4P | G31: =169.1 -> 169.1 | J31: AT 09/09-AR | K31: 101 | L31: 9.5
A32: 1SPZ63 | B32: 240000 | F32: Motor 4kW-4P | G32: =208.5 -> 208.5 | J32: AT 09/07-AR | K32: 98 | L32: 8.3
A33: 1SPZ67 | B33: 250000 | F33: Motor 5.5kW-4P | G33: =290 -> 290 | J33: AT 10/10-AR | K33: 100 | L33: 11
A34: 1SPZ71 | B34: 260000 | F34: Motor 7.5kW-4P | G34: =362.9 -> 362.9 | J34: AT 10/08-AR | K34: 99 | L34: 9.8
A35: 1SPZ75 | B35: 320000 | F35: Motor 11kW-4P | G35: =507.6 -> 507.6 | J35: AT 12/12-AR | K35: 128 | L35: 18.4
A36: 1SPZ80 | B36: 330000 | F36: Motor 15kW-4P | G36: =639.4 -> 639.4 | J36: AT 12/12-AR | K36: 141 | L36: 18.4
A37: 1SPZ85 | B37: 350000 | F37: Motor 18.5kW-4P | G37: =810.6 -> 810.6 | J37: AT 12/12-AR | K37: 121 | L37: 18.4
A38: 1SPZ90 | B38: 350000 | F38: Motor 22kW-4P | G38: =911.6 -> 911.6 | J38: AT 12/09-AR | K38: 117 | L38: 16
A39: 1SPZ95 | B39: 360000 | F39: Motor 30kW-4P | G39: =1252.8 -> 1252.8 | J39: AT 15/15-AR | K39: 146 | L39: 24.5
A40: 1SPZ100 | B40: 390000 | F40: Motor 37kW-4P | G40: =1400.3 -> 1400.3 | J40: AT 15/15-AR | K40: 186 | L40: 24.5
...

Sheet SCU75M1
A1: X | C1: 1 | D1: 2 | E1: 3 | F1: 4 | G1: 5 | H1: 6 | I1: 7 | J1: 8 | K1: 9 | L1: 10 | M1: 11 | N1: 12 | O1: 13 | P1: 14 | Q1: 15 | R1: 16 | S1: 17 | T1: 18 | U1: 19 | V1: 20 | W1: 21 | X1: 22 | Y1: 23 | Z1: 24 | AA1: XXXXXXXX | AB1: X | AC1: XXXXXXXX | AD1: XXXXXXXX | AE1: XXXXXXXX | AF1: XXXXXXXX | AG1: X | AH1: X | AI1: X | AN1: X | AO1: X | AP1: X | AU1: X | AV1: X | AW1: X | BE1: X | BF1: X | BG1: X | BP1: X | BY1: X | CH1: X | CI1: X
B2: Casing Spec: SCU- | U2: =+B73 -> SCU75M1 | Y2: =+Y646 -> 177.79686 | Z2: =+Z646 -> 878.4747 | AA2: SCU75M1 | AC2: SCU75M1 | AD2: SCU100M1 | AE2: SCU125M1 | AF2: SCU150M1
B3: Specification Casing | D3: Frame | E3: Ambient | F3: Coat(Frm) | G3: Liner 1 (mmT) | I3: Liner 2 (mmT) | K3: Coat(Liner) | L3: Insulation | M3: Panel | N3: Coat(Pnl) | O3: Structure | P3: Coat(Skd) | Q3: Coat(Str) | R3: DrainPan | S3: Coat(DP)
B4: Entry==> | D4: 1540T(NA06) | E4: SA | F4: 1 | G4: GI | H4: 0 | I4: 0 | J4: 0 | K4: 1 | L4: 0 | M4: SGCC | N4: 1 | O4: SGCC | P4: 1 | Q4: 0 | R4: SUS316L | S4: 0
B5: Specification Coil | D5: Fin (DXC/CWC) | F5: Tube (DXC/CWC) | H5: EP (DXC/CWC) | J5: Header | K5: AGC | L5: VR514 | M5: UC5504
B6: Entry==> | D6: Al1100 | E6: 0.11 | F6: Cu | G6: 0.33 | H6: SGCC | I6: 1.5 | J6: Copper | K6: 1 | L6: 1 | M6: 0
B7: Specification Component | D7: Compressor | E7: Blower | F7: Axial Fan | G7: Enclosure | H7: LCS | I7: Rfg PT | J7: Rfg PG | K7: CC Heater | L7: S. Accum. | M7: FD/SG | N7: Ball Valve | O7: Cable | U7: Skid Rpt | V7: WPS | W7: MPT | X7: Load Test | Y7: FAT | Z7: ATEX
B8: Entry==> | D8: Copeland | E8: NA | F8: WeiGuang | G8: Std IP44 | H8: 0 | I8: 0 | J8: 0 | K8: 0 | L8: 0 | M8: 0 | N8: 0 | O8: 1 Core | U8: 0 | V8: 0 | W8: 0 | X8: 0 | Y8: 0 | Z8: 0
B9: Structure & Coating | D9: Casing Structure | G9: DrainPan | J9: Nylon-Coat | L9: Frame-Coat | N9: Liner-Coat | P9: Panel-Coat | R9: Skid-Hot Dip | T9: Structure-Coat | V9: DrainPan-Coat | Y9: Rp/USD | Z9: =+Z17 -> 14654
D10: Type | E10: kG/m3 | F10: Rp/kG | G10: Type | H10: kG/m3 | I10: Rp/kG | J10: kG/m2 | K10: Rp/m2 | L10: kG/m2 | M10: Rp/m2 | N10: kG/m2 | O10: Rp/m2 | P10: kG/m2 | Q10: Rp/kG | R10: kG/m2 | S10: Rp/kG | T10: kG/m2 | U10: Rp/m2 | V10: kG/m2 | W10: Rp/m2
D11: =+O4 -> SGCC | E11: =VLOOKUP($D11,$D$12:$F$18,2,FALSE) -> 8030 | F11: =VLOOKUP($D11,$D$12:$F$18,3,FALSE) -> 22500 | G11: =+R4 -> SUS316L | H11: =VLOOKUP($G11,$G$12:$I$18,2,FALSE) -> 8000 | I11: =VLOOKUP($G11,$G$12:$I$18,3,FALSE) -> 80000 | J11: =SUM(J12:J18)*F4 -> 0.372 | K11: =SUM(K12:K18)*F4 -> 105216.78 | L11: =SUM(L12:L18)*F4 -> 0.25 | M11: =SUM(M12:M18)*F4 -> 65000 | N11: =SUM(N12:N18)*K4 -> 0.25 | O11: =SUM(O12:O18)*K4 -> 65000 | P11: =SUM(P12:P18)*N4 -> 0.25 | Q11: =SUM(Q12:Q18)*N4 -> 65000 | R11: =SUM(R12:R18)*P4 -> 0.4284 | S11: =SUM(S12:S18)*P4 -> 9000 | T11: =SUM(T12:T18)*Q4 -> 0 | U11: =SUM(U12:U18)*Q4 -> 0 | V11: =SUM(V12:V18)*S4 -> 0 | W11: =SUM(W12:W18)*S4 -> 0
D12: SGCC | E12: 8030 | F12: 22500 | G12: SGCC | H12: 8030 | I12: 22500 | J12: 0.372 | K12: =7.25632959950898*14500 -> 105216.78 | L12: 0.25 | M12: 65000 | N12: 0.25 | O12: 65000 | P12: 0.25 | Q12: 65000 | R12: =60/1000000*7140 -> 0.4284 | S12: 9000 | T12: 0.25 | U12: 65000 | V12: 0.25 | W12: 65000 | Y12: USD | Z12: 1
D13: SPHC | E13: 7700 | F13: 18000 | G13: SPHC | H13: 7700 | I13: 18000 | Y13: Euro | Z13: 0.882
D14: SUS304 | E14: 7800 | F14: 65000 | G14: SUS304 | H14: 7800 | I14: 65000 | Y14: SGP | Z14: 1.375
D15: SUS316L | E15: 8000 | F15: 80000 | G15: SUS316L | H15: 8000 | I15: 80000 | Y15: RM | Z15: 4.186
D16: Al6063 | E16: 2720 | F16: =83085+(65000-54000) -> 94085 | G16: Al6063 | H16: 2720 | I16: =83085+(65000-54000) -> 94085 | Y16: Rmb | Z16: 6.935
D17: Copper | E17: 8900 | F17: 207000 | G17: Copper | H17: 8900 | I17: 207000 | Y17: Rp | Z17: 14654
Y18: Rs | Z18: 71.907
B19: Frame | D19: Pentapost | F19: Centerpost | H19: Cornerpiece | J19: Omega Joint | L19: Panel Clip | N19: Coating Area | R19: Cutting Allowance
C20: Type | D20: kG/m | E20: Rp/m | F20: kG/m | G20: Rp/m | H20: kG/Pc | I20: Rp/Pc | J20: kG/Pc | K20: Rp/Pc | L20: kG/m | M20: Rp/m | N20: Corner | O20: PP | P20: CP | Q20: CLIP | R20: PP | S20: CP | T20: Insert | U20: Gsk | V20: Clip L | W20: Clip H | X20: Pnl PP | Y20: Pnl CP
C21: =+D$4 -> 1540T(NA06) | D21: =VLOOKUP($C21,$C$22:$Y$40,2,FALSE) -> 0.711 | E21: =VLOOKUP($C21,$C$22:$Y$40,3,FALSE) -> 46215 | F21: =VLOOKUP($C21,$C$22:$Y$40,4,FALSE) -> 0.539 | G21: =VLOOKUP($C21,$C$22:$Y$40,5,FALSE) -> 35035 | H21: =VLOOKUP($C21,$C$22:$Y$40,6,FALSE) -> 0.123886 | I21: =VLOOKUP($C21,$C$22:$Y$40,7,FALSE) -> 7000 | J21: =VLOOKUP($C21,$C$22:$Y$40,8,FALSE) -> 0 | K21: =VLOOKUP($C21,$C$22:$Y$40,9,FALSE) -> 0 | L21: =VLOOKUP($C21,$C$22:$Y$40,10,FALSE) -> 0 | M21: =VLOOKUP($C21,$C$22:$Y$40,11,FALSE) -> 0 | N21: =VLOOKUP($C21,$C$22:$X$40,12,FALSE) -> 115 | O21: =VLOOKUP($C21,$C$22:$X$40,13,FALSE) -> 198 | P21: =VLOOKUP($C21,$C$22:$X$40,14,FALSE) -> 198 | Q21: =VLOOKUP($C21,$C$22:$X$40,15,FALSE) -> 0 | R21: =VLOOKUP($C21,$C$22:$Y$40,16,FALSE) -> 60 | S21: =VLOOKUP($C21,$C$22:$Y$40,17,FALSE) -> 40 | T21: =VLOOKUP($C21,$C$22:$Y$40,18,FALSE) -> 0 | U21: =VLOOKUP($C21,$C$22:$Y$40,19,FALSE) -> 40 | V21: =VLOOKUP($C21,$C$22:$Y$40,20,FALSE) -> 0 | W21: =VLOOKUP($C21,$C$22:$Y$40,21,FALSE) -> 0 | X21: =VLOOKUP($C21,$C$22:$Y$40,22,FALSE) -> 40 | Y21: =VLOOKUP($C21,$C$22:$Y$40,23,FALSE) -> 40
C22: No Frame | D22: 0 | E22: 0 | F22: 0 | G22: 0 | H22: 0 | I22: 0 | J22: 0 | K22: 0 | L22: 0 | M22: =L22*(IF($E$4="NA6",54000,59500)) -> 0 | N22: 0 | O22: 0 | P22: 0 | Q22: 0 | R22: 0 | S22: 0 | T22: 0 | U22: 0 | V22: 0 | W22: 0 | X22: 0 | Y22: 0
C23: 1520T(NA06) | D23: 0.316 | E23: =0.316*65000 -> 20540 | F23: 0.3986 | G23: =0.399*65000 -> 25935 | H23: 0.12 | I23: 7000 | J23: 0 | K23: 0 | L23: 0 | M23: =L23*(IF($E$4="NA6",54000,59500)) -> 0 | N23: 84 | O23: 136 | P23: 136 | Q23: 0 | R23: 35 | S23: 20 | T23: 0 | U23: 20 | V23: 0 | W23: 0 | X23: 20 | Y23: 20
C24: 1520T(NA20) | D24: 0.316 | E24: =0.316*70500 -> 22278 | F24: 0.3986 | G24: =0.399*70500 -> 28129.5 | H24: 0.12 | I24: 7000 | J24: 0 | K24: 0 | L24: 0 | M24: =L24*(IF($E$4="NA6",54000,59500)) -> 0 | N24: 84 | O24: 136 | P24: 136 | Q24: 0 | R24: 35 | S24: 20 | T24: 0 | U24: 20 | V24: 0 | W24: 0 | X24: 20 | Y24: 20
C25: 1540T(NA06) | D25: 0.711 | E25: =0.711*65000 -> 46215 | F25: 0.539 | G25: =0.539*65000 -> 35035 | H25: 0.123886 | I25: 7000 | J25: 0 | K25: 0 | L25: 0 | M25: =L25*(IF($E$4="NA6",54000,59500)) -> 0 | N25: 115 | O25: 198 | P25: 198 | Q25: 0 | R25: 60 | S25: 40 | T25: 0 | U25: 40 | V25: 0 | W25: 0 | X25: 40 | Y25: 40
C26: 1540T(NA20) | D26: 0.711 | E26: =0.711*70500 -> 50125.5 | F26: 0.539 | G26: =0.539*70500 -> 37999.5 | H26: 0.123886 | I26: 7000 | J26: 0 | K26: 0 | L26: 0 | M26: =L26*(IF($E$4="NA6",54000,59500)) -> 0 | N26: 115 | O26: 198 | P26: 198 | Q26: 0 | R26: 60 | S26: 40 | T26: 0 | U26: 40 | V26: 0 | W26: 0 | X26: 40 | Y26: 40
C27: 2540Y(NA06) | D27: =0.647+0.354+0.168*2 -> 1.337 | E27: =(0.647+0.354)*65000+7000*2 -> 79065 | F27: =0.392+0.521+0.168*2 -> 1.249 | G27: =(0.392+0.521)*65000+7000*2 -> 73345 | H27: 0.13427 | I27: =12/6.3*1.16*14700 -> 32480 | J27: 0.035 | K27: 4000 | L27: 0.179 | M27: =0.179*65000 -> 11635 | N27: 95 | O27: 244 | P27: 201 | Q27: 14 | R27: 84 | S27: 84 | T27: 26 | U27: 40 | V27: 60 | W27: 75 | X27: 56 | Y27: 34
C28: 2540Y(NA20) | D28: =0.647+0.354+0.168*2 -> 1.337 | E28: =(0.647+0.354)*70500+7000*2 -> 84570.5 | F28: =0.392+0.521+0.168*2 -> 1.249 | G28: =(0.392+0.521)*70500+7000*2 -> 78366.5 | H28: 0.13427 | I28: =12/6.3*1.16*14700 -> 32480 | J28: 0.035 | K28: 4000 | L28: 0.179 | M28: =0.179*70500 -> 12619.5 | N28: 95 | O28: 244 | P28: 201 | Q28: 14 | R28: 84 | S28: 84 | T28: 26 | U28: 40 | V28: 60 | W28: 75 | X28: 56 | Y28: 34
C29: 5060Y(NA06) | D29: =1.083+0.354+0.168*2 -> 1.773 | E29: =(1.083+0.354)*85000+7000*2 -> 136145 | F29: =0.571+0.521+0.168*2 -> 1.428 | G29: =(0.571+0.52)*85000+7000*2 -> 106735 | H29: 0.42476 | I29: =2.8*1.16*14700 -> 47745.6 | J29: 0.056628 | K29: =5/6.3*1.16*14700 -> 13533.333 | L29: 0.179 | M29: =0.179*65000 -> 11635 | N29: 140 | O29: 334 | P29: 240 | Q29: 14 | R29: 58 | S29: 58 | T29: 52 | U29: 67 | V29: 28 | W29: 58 | X29: 82 | Y29: 34
C30: 5060Y(NA20) | D30: =1.083+0.354+0.168*2 -> 1.773 | E30: =(1.083+0.354)*85000+7000*2 -> 136145 | F30: =0.571+0.521+0.168*2 -> 1.428 | G30: =(0.571+0.52)*85000+7000*2 -> 106735 | H30: 0.42476 | I30: =2.8*1.16*14700 -> 47745.6 | J30: 0.056628 | K30: =5/6.3*1.16*14700 -> 13533.333 | L30: 0.179 | M30: =0.179*70500 -> 12619.5 | N30: 140 | O30: 334 | P30: 240 | Q30: 14 | R30: 58 | S30: 58 | T30: 52 | U30: 67 | V30: 28 | W30: 58 | X30: 82 | Y30: 34
C31: 5060N(NA06) | D31: 1.61207 | E31: =IF($E$4="NA6",154.6/6,183.97/6)*1.16*3570 -> 126976.09 | F31: 1.2431 | G31: =IF($E$4="NA6",119.15/6,137.78/6)*1.16*3570 -> 95095.756 | H31: 0.21 | I31: =14.15*1.16*3570 -> 58597.98 | J31: 0.04 | K31: =4.3*1.16*3570 -> 17807.16 | L31: 0.17758621 | M31: =17.25/6*1.16*3570 -> 11905.95 | N31: 140 | O31: 334 | P31: 240 | Q31: 14 | R31: 80 | S31: 80 | T31: 0 | U31: 80 | V31: 80 | W31: 80 | X31: 62 | Y31: 42
C32: 5060A(NA20) | D32: 1.9327586 | E32: =IF($E$4="NA6",223.3/6,265.83/6)*1.16*3570 -> 183475.87 | F32: 1.5689655 | G32: =IF($E$4="NA6",193.45/6,223.7/6)*1.16*3570 -> 154397.74 | H32: 0.21 | I32: =14.15*1.16*3570 -> 58597.98 | J32: 0.04 | K32: =4.3*1.16*3570 -> 17807.16 | L32: 0.17758621 | M32: =19.95/6*1.16*3570 -> 13769.49 | N32: 140 | O32: 334 | P32: 240 | Q32: 14 | R32: 80 | S32: 80 | T32: 0 | U32: 80 | V32: 80 | W32: 80 | X32: 62 | Y32: 42
C33: 2550T(304) | D33: 4.969 | E33: 182255 | F33: 4.225 | G33: 150824 | H33: 0.772 | I33: 31390 | J33: 0.062 | K33: 3719 | L33: 0 | M33: 0 | N33: 0 | O33: 0 | P33: 0 | Q33: 0 | R33: 50 | S33: 50 | T33: 0 | U33: 50 | V33: 0 | W33: 0 | X33: 50 | Y33: 50
C34: 2550T(316) | D34: 5.081 | E34: 271704 | F34: 4.317 | G34: 224300 | H34: 0.792 | I34: 47203 | J34: 0.064 | K34: 3814 | L34: 0 | M34: 0 | N34: 0 | O34: 0 | P34: 0 | Q34: 0 | R34: 50 | S34: 50 | T34: 0 | U34: 50 | V34: 0 | W34: 0 | X34: 50 | Y34: 50
C35: 5070T(304) | D35: 6.147 | E35: 232434 | F35: 5.005 | G35: 182531 | H35: 1.914 | I35: 77809 | J35: 0.094 | K35: 3805 | L35: 0 | M35: 0 | N35: 0 | O35: 0 | P35: 0 | Q35: 0 | R35: 70 | S35: 50 | T35: 0 | U35: 70 | V35: 0 | W35: 0 | X35: 70 | Y35: 50
C36: 5070T(316) | D36: 6.291 | E36: 347439 | F36: 5.117 | G36: 271980 | H36: 1.963 | I36: 117007 | J36: 0.096 | K36: 5722 | L36: 0 | M36: 0 | N36: 0 | O36: 0 | P36: 0 | Q36: 0 | R36: 70 | S36: 50 | T36: 0 | U36: 70 | V36: 0 | W36: 0 | X36: 70 | Y36: 50
C37: 2540A(304) | D37: 2.074 | E37: 745100 | F37: 1.897 | G37: 792400 | H37: 0.31 | I37: 740100 | J37: 0.094 | K37: 176300 | L37: 0 | M37: 0 | N37: 0 | O37: 0 | P37: 0 | Q37: 0 | R37: 60 | S37: 60 | T37: 0 | U37: 40 | V37: 0 | W37: 0 | X37: 60 | Y37: 60
C38: 2540A(316) | D38: 2.074 | E38: 875200 | F38: 1.897 | G38: 922500 | H38: 0.31 | I38: 740100 | J38: 0.094 | K38: 176300 | L38: 0 | M38: 0 | N38: 0 | O38: 0 | P38: 0 | Q38: 0 | R38: 60 | S38: 60 | T38: 0 | U38: 40 | V38: 0 | W38: 0 | X38: 40 | Y38: 40
C39: 4550A(304) | D39: 2.63 | E39: 875200 | F39: 2.61 | G39: 863300 | H39: 0.494 | I39: 775300 | J39: 0.15 | K39: 176300 | L39: 0 | M39: 0 | N39: 0 | O39: 0 | P39: 0 | Q39: 0 | R39: 70 | S39: 70 | T39: 0 | U39: 50 | V39: 0 | W39: 0 | X39: 50 | Y39: 50
C40: 4550A(316) | D40: 2.63 | E40: 898800 | F40: 2.61 | G40: 887000 | H40: 0.494 | I40: 775300 | J40: 0.15 | K40: 176300 | L40: 0 | M40: 0 | N40: 0 | O40: 0 | P40: 0 | Q40: 0 | R40: 70 | S40: 70 | T40: 0 | U40: 50 | V40: 0 | W40: 0 | X40: 50 | Y40: 50
...

Sheet AHU IU1
D1: H | E1: D | F1: W | K1: Profile | L1: Section No.
D2: 1420 | E2: 3250 | F2: 1930 | G2: =E2/1000*F2/1000 -> 6.2725 | H2: 110 | J2: DS | K2: 5060Y(NA06) | L2: 2
D3: =ROUND((D2-100)/305,0) -> 4 | F3: =ROUND((F2-100)/305,0) -> 6 | H3: 1453.66 | I3: RM
B4: NO | C4: DESCRIPTION | D4: Unit Costing
D5: Usage | F5: Price (Fcy) | H5: Factors | K5: Cost (US$)
D6: Uom | E6: Qty | F6: U/P(Fcy) | H6: EF | I6: LF | J6: WF | K6: U/C | L6: Total | M6: Sub Total | Y6: t | Z6: h | AA6: w | AB6: @ | AC6: kg | AD6: qty | AE6: kg total | AF6: rp | AG6: Material | AH6: Bending | AI6: Total
H7: 17500 | X7: W | Y7: 2 | Z7: =F2 -> 1930 | AA7: 250 | AB7: 7860 | AC7: =AB7*AA7/1000*Z7/1000*Y7/1000 -> 7.5849 | AD7: 2 | AE7: =AC7*AD7 -> 15.1698 | AF7: 21500 | AG7: =AE7*AF7 -> 326150.7 | AH7: =8*3000 -> 24000 | AI7: =AG7+AH7 -> 350150.7
B8: FRAME | P8: PROFILE TYPE | Q8: H | R8: D | S8: W | X8: D | Y8: 2 | Z8: =E2 -> 3250 | AA8: 250 | AB8: 7860 | AC8: =AB8*AA8/1000*Z8/1000*Y8/1000 -> 12.7725 | AD8: 2 | AE8: =AC8*AD8 -> 25.545 | AF8: 21500 | AG8: =AE8*AF8 -> 549217.5 | AH8: =3*3000 -> 9000 | AI8: =AG8+AH8 -> 558217.5
B9: 1 | C9: ="PENTAPOST DS" &$K$2& "H" -> PENTAPOST DS5060Y(NA06)H | D9: M | E9: =VLOOKUP($K$2,'AHU IU1'!$P$9:$S$26,2,0) -> 10.016 | F9: RP | G9: =VLOOKUP($K$2,Master!$O$4:$Y$21,3,0) -> 174015 | H9: =IF(F9="Rp",1/$H$7,1) -> 5.7142857e-05 | I9: 1 | J9: 1.05 | K9: =+G9*H9*I9*J9 -> 10.4409 | L9: 0 | N9: =VLOOKUP($K$2,Master!$O$4:$Y$21,2,0)*E9 -> 17.758368 | P9: 1520T(NA06) | Q9: =(('AHU IU1'!$D$2-(35*2))*4/1000)*'AHU IU1'!$L$2 -> 10.8 | R9: =(('AHU IU1'!$E$2-(35*2))*4/1000)*'AHU IU1'!$L$2 -> 25.44 | S9: =(('AHU IU1'!$F$2-(35*2))*4/1000)*'AHU IU1'!$L$2 -> 14.88 | U9: 17064 | V9: 21524.4 | X9: H | Y9: 2 | Z9: =D2 -> 1420 | AA9: 200 | AB9: 7860 | AC9: =AB9*AA9/1000*Z9/1000*Y9/1000 -> 4.46448 | AD9: 2 | AE9: =AC9*AD9 -> 8.92896 | AF9: 21500 | AG9: =AE9*AF9 -> 191972.64 | AH9: =3*3000 -> 9000 | AI9: =AG9+AH9 -> 200972.64
B10: 2 | C10: ="PENTAPOST DS" &$K$2& "D" -> PENTAPOST DS5060Y(NA06)D | D10: M | E10: =VLOOKUP($K$2,'AHU IU1'!$P$9:$S$26,3,0) -> 24.656 | F10: RP | G10: =G9 -> 174015 | H10: =IF(F10="Rp",1/$H$7,1) -> 5.7142857e-05 | I10: 1 | J10: 1.05 | K10: =+G10*H10*I10*J10 -> 10.4409 | L10: 0 | N10: =VLOOKUP($K$2,Master!$O$4:$Y$21,2,0)*E10 -> 43.715088 | P10: 1520T(NA20) | Q10: =(('AHU IU1'!$D$2-(35*2))*4/1000)*'AHU IU1'!$L$2 -> 10.8 | R10: =(('AHU IU1'!$E$2-(35*2))*4/1000)*'AHU IU1'!$L$2 -> 25.44 | S10: =(('AHU IU1'!$F$2-(35*2))*4/1000)*'AHU IU1'!$L$2 -> 14.88 | U10: 38394 | V10: 29106 | X10: Support Blower | Y10: 2 | Z10: =Z7 -> 1930 | AA10: 300 | AB10: 7860 | AC10: =AB10*AA10/1000*Z10/1000*Y10/1000 -> 9.10188 | AD10: 2 | AE10: =AC10*AD10 -> 18.20376 | AF10: 21500 | AG10: =AE10*AF10 -> 391380.84 | AH10: =6*3000 -> 18000 | AI10: =AG10+AH10 -> 409380.84
B11: 3 | C11: ="PENTAPOST DS" &$K$2& "W" -> PENTAPOST DS5060Y(NA06)W | D11: M | E11: =VLOOKUP($K$2,'AHU IU1'!$P$9:$S$26,4,0) -> 14.096 | F11: RP | G11: =G9 -> 174015 | H11: =IF(F11="Rp",1/$H$7,1) -> 5.7142857e-05 | I11: 1 | J11: 1.05 | K11: =+G11*H11*I11*J11 -> 10.4409 | L11: 0 | N11: =VLOOKUP($K$2,Master!$O$4:$Y$21,2,0)*E11 -> 24.992208 | P11: 1540T(NA06) | Q11: =(('AHU IU1'!$D$2-(59*2))*4/1000)*'AHU IU1'!$L$2 -> 10.416 | R11: =(('AHU IU1'!$E$2-(59*2))*4/1000)*'AHU IU1'!$L$2 -> 25.056 | S11: =(('AHU IU1'!$F$2-(59*2))*4/1000)*'AHU IU1'!$L$2 -> 14.496 | U11: 67054 | V11: 62302 | X11: Channel Atas | Y11: 1.5 | Z11: =Z8/2 -> 1625 | AA11: 250 | AB11: 7860 | AC11: =AB11*AA11/1000*Z11/1000*Y11/1000 -> 4.7896875 | AD11: 4 | AE11: =AC11*AD11 -> 19.15875 | AF11: 16000 | AG11: =AE11*AF11 -> 306540
B12: 4 | C12: ="CENTERPOST DS" &$K$2& "H" -> CENTERPOST DS5060Y(NA06)H | D12: M | E12: =((D2-(35*2))/1000)*2 -> 2.7 | F12: RP | G12: =VLOOKUP($K$2,Master!$O$4:$Y$21,5,0) -> 131975 | H12: =IF(F12="Rp",1/$H$7,1) -> 5.7142857e-05 | I12: 1 | J12: 1.05 | K12: =+G12*H12*I12*J12 -> 7.9185 | L12: 0 | N12: =VLOOKUP($K$2,Master!$O$4:$Y$21,4,0)*E12 -> 2.9511 | P12: 1540T(NA20) | Q12: =(('AHU IU1'!$D$2-(59*2))*4/1000)*'AHU IU1'!$L$2 -> 10.416 | R12: =(('AHU IU1'!$E$2-(59*2))*4/1000)*'AHU IU1'!$L$2 -> 25.056 | S12: =(('AHU IU1'!$F$2-(59*2))*4/1000)*'AHU IU1'!$L$2 -> 14.496 | U12: 90598 | V12: 71914 | X12: Support | Y12: 1.5 | Z12: =E2 -> 3250 | AA12: 200 | AB12: 7860 | AC12: =AB12*AA12/1000*Z12/1000*Y12/1000 -> 7.6635 | AD12: 4 | AE12: =AC12*AD12 -> 30.654 | AF12: 16000 | AG12: =AE12*AF12 -> 490464
B13: 5 | C13: ="CENTERPOST DS" &$K$2& "D" -> CENTERPOST DS5060Y(NA06)D | D13: M | E13: =((E2-(35*2))/1000)*1 -> 3.18 | F13: RP | G13: =G12 -> 131975 | H13: =IF(F13="Rp",1/$H$7,1) -> 5.7142857e-05 | I13: 1 | J13: 1.05 | K13: =+G13*H13*I13*J13 -> 7.9185 | L13: 0 | N13: =VLOOKUP($K$2,Master!$O$4:$Y$21,4,0)*E13 -> 3.47574 | P13: 2540Y(NA06) | Q13: =(('AHU IU1'!$D$2-(58*2))*4/1000)*'AHU IU1'!$L$2 -> 10.432 | R13: =(('AHU IU1'!$E$2-(58*2))*4/1000)*'AHU IU1'!$L$2 -> 25.072 | S13: =(('AHU IU1'!$F$2-(58*2))*4/1000)*'AHU IU1'!$L$2 -> 14.512 | AE13: =SUM(AE7:AE12) -> 117.66027 | AG13: =SUM(AG7:AG12) -> 2255725.7 | AH13: =AG13/14500 -> 155.56729
B14: 6 | C14: ="CENTERPOST DS" &$K$2& "Door" -> CENTERPOST DS5060Y(NA06)Door | D14: M | E14: =(((E2/2)-(35*2))/1000)*2 -> 3.11 | F14: RP | G14: =G13 -> 131975 | H14: =IF(F14="Rp",1/$H$7,1) -> 5.7142857e-05 | I14: 1 | J14: 1.05 | K14: =+G14*H14*I14*J14 -> 7.9185 | L14: 0 | N14: =VLOOKUP($K$2,Master!$O$4:$Y$21,4,0)*E14 -> 3.39923 | P14: 2540Y(NA20) | Q14: =(('AHU IU1'!$D$2-(58*2))*4/1000)*'AHU IU1'!$L$2 -> 10.432 | R14: =(('AHU IU1'!$E$2-(58*2))*4/1000)*'AHU IU1'!$L$2 -> 25.072 | S14: =(('AHU IU1'!$F$2-(58*2))*4/1000)*'AHU IU1'!$L$2 -> 14.512 | U14: 35 | V14: 40
B15: 7 | C15: ="CENTERPOST DS" &$K$2& "W" -> CENTERPOST DS5060Y(NA06)W | D15: M | E15: =((F2-(35*2))/1000)*2 -> 3.72 | F15: RP | G15: =G12 -> 131975 | H15: =IF(F15="Rp",1/$H$7,1) -> 5.7142857e-05 | I15: 1 | J15: 1.05 | K15: =+G15*H15*I15*J15 -> 7.9185 | L15: 0 | N15: =VLOOKUP($K$2,Master!$O$4:$Y$21,4,0)*E15 -> 4.06596 | P15: 5060Y(NA06) | Q15: =(('AHU IU1'!$D$2-(84*2))*4/1000)*'AHU IU1'!$L$2 -> 10.016 | R15: =(('AHU IU1'!$E$2-(84*2))*4/1000)*'AHU IU1'!$L$2 -> 24.656 | S15: =(('AHU IU1'!$F$2-(84*2))*4/1000)*'AHU IU1'!$L$2 -> 14.096 | U15: 59 | V15: 80
B16: 8 | C16: PANEL CLIP BIG | D16: M | E16: =SUM(E9:E15)*2 -> 122.956 | F16: RP | G16: =VLOOKUP($K$2,Master!$O$4:$Y$21,11,0) -> 15150 | H16: =IF(F16="Rp",1/$H$7,1) -> 5.7142857e-05 | I16: 1 | J16: 1.05 | K16: =+G16*H16*I16*J16 -> 0.909 | L16: 0 | N16: =VLOOKUP($K$2,Master!$O$4:$Y$21,10,0)*E16 -> 24.837112 | P16: 5060Y(NA20) | Q16: =(('AHU IU1'!$D$2-(84*2))*4/1000)*'AHU IU1'!$L$2 -> 10.016 | R16: =(('AHU IU1'!$E$2-(84*2))*4/1000)*'AHU IU1'!$L$2 -> 24.656 | S16: =(('AHU IU1'!$F$2-(84*2))*4/1000)*'AHU IU1'!$L$2 -> 14.096 | U16: 58 | V16: 82
B17: 9 | C17: PANEL CLIP SMALL | D17: M | E17: =E16/4 -> 30.739 | F17: RP | G17: =G16 -> 15150 | H17: =IF(F17="Rp",1/$H$7,1) -> 5.7142857e-05 | I17: 1 | J17: 1.05 | K17: =+G17*H17*I17*J17 -> 0.909 | L17: 0 | N17: =VLOOKUP($K$2,Master!$O$4:$Y$21,10,0)*E17 -> 6.209278 | P17: 5060N(NA06) | Q17: =(('AHU IU1'!$D$2-(80*2))*4/1000)*'AHU IU1'!$L$2 -> 10.08 | R17: =(('AHU IU1'!$E$2-(80*2))*4/1000)*'AHU IU1'!$L$2 -> 24.72 | S17: =(('AHU IU1'!$F$2-(80*2))*4/1000)*'AHU IU1'!$L$2 -> 14.16 | U17: 84 | V17: 134
B18: 10 | C18: RUBBER INSERT | D18: M | E18: =SUM(E16:E17) -> 153.695 | F18: RP | G18: 10000 | H18: =IF(F18="Rp",1/$H$7,1) -> 5.7142857e-05 | I18: 1 | J18: 1.05 | K18: =+G18*H18*I18*J18 -> 0.6 | L18: 0 | P18: 5060A(NA20) | Q18: =(('AHU IU1'!$D$2-(80*2))*4/1000)*'AHU IU1'!$L$2 -> 10.08 | R18: =(('AHU IU1'!$E$2-(80*2))*4/1000)*'AHU IU1'!$L$2 -> 24.72 | S18: =(('AHU IU1'!$F$2-(80*2))*4/1000)*'AHU IU1'!$L$2 -> 14.16
B19: 11 | C19: GASKET | D19: M | E19: =E18 -> 153.695 | F19: RP | G19: 10000 | H19: =IF(F19="Rp",1/$H$7,1) -> 5.7142857e-05 | I19: 1 | J19: 1.05 | K19: =+G19*H19*I19*J19 -> 0.6 | L19: 0 | P19: 2550T(304) | Q19: =(('AHU IU1'!$D$2-(50*2))*4/1000)*'AHU IU1'!$L$2 -> 10.56 | R19: =(('AHU IU1'!$E$2)*4/1000)*'AHU IU1'!$L$2 -> 26 | S19: =(('AHU IU1'!$F$2)*4/1000)*'AHU IU1'!$L$2 -> 15.44
B20: 12 | C20: ="CORNERPIECE DS"&$K$2 -> CORNERPIECE DS5060Y(NA06) | D20: PCS | E20: =8*L2 -> 16 | F20: RP | G20: =VLOOKUP($K$2,Master!$O$4:$Y$21,7,0) -> 84000 | H20: =IF(F20="Rp",1/$H$7,1) -> 5.7142857e-05 | I20: 1 | J20: 1 | K20: =+G20*H20*I20*J20 -> 4.8 | L20: 0 | N20: =VLOOKUP($K$2,Master!$O$4:$Y$21,6,0)*E20 -> 6.79616 | P20: 2550T(316) | Q20: =(('AHU IU1'!$D$2-(50*2))*4/1000)*'AHU IU1'!$L$2 -> 10.56 | R20: =(('AHU IU1'!$E$2)*4/1000)*'AHU IU1'!$L$2 -> 26 | S20: =(('AHU IU1'!$F$2)*4/1000)*'AHU IU1'!$L$2 -> 15.44
B21: 13 | C21: ="OMEGA JOINT DS"&$K$2 -> OMEGA JOINT DS5060Y(NA06) | D21: PCS | E21: =2*((E12/((D2-(35*2))/1000))+(E13/((E2-(35*2))/1000))+(E14/(((E2/2)-(35*2))/1000))+(E15/((F2-(35*2))/1000))) -> 14 | F21: RP | G21: =VLOOKUP($K$2,Master!$O$4:$Y$21,9,0) -> 24000 | H21: =IF(F21="Rp",1/$H$7,1) -> 5.7142857e-05 | I21: 1 | J21: 1 | K21: =+G21*H21*I21*J21 -> 1.3714286 | L21: =M21/H7 -> 945.25369 | M21: ='2. AHU-Frame & Panel'!O96 -> 16541940 | N21: =VLOOKUP($K$2,Master!$O$4:$Y$21,8,0)*E21 -> 0.792792 | P21: 5070T(304) | Q21: =(('AHU IU1'!$D$2-(70*2))*4/1000)*'AHU IU1'!$L$2 -> 10.24 | R21: =(('AHU IU1'!$E$2)*4/1000)*'AHU IU1'!$L$2 -> 26 | S21: =(('AHU IU1'!$F$2)*4/1000)*'AHU IU1'!$L$2 -> 15.44
B22: LEG/SKID | P22: 5070T(316) | Q22: =(('AHU IU1'!$D$2-(70*2))*4/1000)*'AHU IU1'!$L$2 -> 10.24 | R22: =(('AHU IU1'!$E$2)*4/1000)*'AHU IU1'!$L$2 -> 26 | S22: =(('AHU IU1'!$F$2)*4/1000)*'AHU IU1'!$L$2 -> 15.44 | T22: 2584 | U22: 892
B23: 14 | C23: Leg | D23: kg | E23: =1.4*AE13 -> 164.72438 | F23: RP | G23: 30000 | H23: =IF(F23="Rp",1/$H$7,1) -> 5.7142857e-05 | I23: 1 | J23: 1.2 | K23: =+G23*H23*I23*J23 -> 2.0571429 | L23: =M23/H7 -> 130.25767 | M23: ='1. AHU-Skid'!O25 -> 2279509.3 | N23: =E23 -> 164.72438 | P23: 2540A(304) | Q23: =(('AHU IU1'!$D$2-(40*2))*4/1000)*'AHU IU1'!$L$2 -> 10.72 | R23: =(('AHU IU1'!$E$2)*4/1000)*'AHU IU1'!$L$2 -> 26 | S23: =(('AHU IU1'!$F$2)*4/1000)*'AHU IU1'!$L$2 -> 15.44 | T23: 2664 | U23: 972
B24: 15 | C24: STRUCTUR | D24: kg | E24: 1 | F24: RP | G24: 0 | H24: =IF(F24="Rp",1/$H$7,1) -> 5.7142857e-05 | I24: 1 | J24: 1 | K24: =+G24*H24*I24*J24 -> 0 | L24: =M24/H7 -> 311.68791 | M24: ='3. AHU-Structure'!O60 -> 5454538.4 | N24: =E24 -> 1 | P24: 2540A(316) | Q24: =(('AHU IU1'!$D$2-(40*2))*4/1000)*'AHU IU1'!$L$2 -> 10.72 | R24: =(('AHU IU1'!$E$2)*4/1000)*'AHU IU1'!$L$2 -> 26 | S24: =(('AHU IU1'!$F$2)*4/1000)*'AHU IU1'!$L$2 -> 15.44 | T24: =T22-T23 -> -80 | U24: =U22-U23 -> -80
B25: FLANGE & FAN CONNECTION | P25: 4550A(304) | Q25: =(('AHU IU1'!$D$2-(50*2))*4/1000)*'AHU IU1'!$L$2 -> 10.56 | R25: =(('AHU IU1'!$E$2)*4/1000)*'AHU IU1'!$L$2 -> 26 | S25: =(('AHU IU1'!$F$2)*4/1000)*'AHU IU1'!$L$2 -> 15.44
B26: 16 | C26: Grill Flange SA | D26: m2 | E26: 0 | F26: RP | G26: 500000 | H26: =IF(F26="Rp",1/$H$7,1) -> 5.7142857e-05 | I26: 1 | J26: 1 | K26: =+G26*H26*I26*J26 -> 28.571429 | L26: =+E26*K26 -> 0 | M26: =L26*16500 -> 0 | P26: 4550A(316) | Q26: =(('AHU IU1'!$D$2-(50*2))*4/1000)*'AHU IU1'!$L$2 -> 10.56 | R26: =(('AHU IU1'!$E$2)*4/1000)*'AHU IU1'!$L$2 -> 26 | S26: =(('AHU IU1'!$F$2)*4/1000)*'AHU IU1'!$L$2 -> 15.44
B27: 17 | C27: Grill Flange RA | D27: m2 | E27: 0 | F27: RP | G27: 500000 | H27: =IF(F27="Rp",1/$H$7,1) -> 5.7142857e-05 | I27: 1 | J27: 1 | K27: =+G27*H27*I27*J27 -> 28.571429 | L27: =+E27*K27 -> 0 | M27: =L27*16500 -> 0
B28: 18 | C28: Blower Duct / Damper RA | D28: SET | E28: 0 | F28: RP | G28: ='VolDamperCost2023 RA '!S59+'VolDamperCost2023 RA '!S92 -> 801647.84 | H28: =IF(F28="Rp",1/$H$7,1) -> 5.7142857e-05 | I28: 1 | J28: 1 | K28: =+G28*H28*I28*J28 -> 45.808448 | L28: =+E28*K28 -> 0 | M28: =L28*16500 -> 0
B29: 19 | C29: Blower Duct / Damper SA | D29: SET | E29: 0 | F29: RP | G29: ='VolDamperCost2023 FA '!S59+'VolDamperCost2023 FA '!S92 -> 801647.84 | H29: =IF(F29="Rp",1/$H$7,1) -> 5.7142857e-05 | I29: 1 | J29: 1 | K29: =+G29*H29*I29*J29 -> 45.808448 | L29: =+E29*K29 -> 0 | M29: =L29*16500 -> 0 | X29: =1.26*0.4 -> 0.504 | Y29: RAG/FAG
B30: PANEL | X30: =350000/X29 -> 694444.44 | Y30: per m2
B31: 20 | C31: PANEL (PU+GI+CB) | D31: M2 | E31: =VLOOKUP($K$2,'AHU IU1'!$P$32:$R$68,3,0) -> 23.826336 | F31: USD | G31: =VLOOKUP($K$2,'AHU IU1'!$P$32:$R$68,2,0) -> 17.676994 | H31: =IF(F31="Rp",1/$H$7,1) -> 1 | I31: 1 | J31: 1.2 | K31: =+G31*H31*I31*J31 -> 21.212393 | L31: =+E31*K31 -> 505.41361 | M31: 0 | N31: =VLOOKUP($K$2,Master!O4:Z21,12,0)/1000*E31*48 -> 57.183206 | P31: PANEL
B32: 21 | C32: PANEL (PU+GI+CB) | D32: PCS | E32: 0 | F32: RP | G32: 52000 | H32: =IF(F32="Rp",1/$H$7,1) -> 5.7142857e-05 | I32: 1 | J32: 1 | K32: =+G32*H32*I32*J32 -> 2.9714286 | L32: =+E32*K32 -> 0 | M32: =L32*15000 -> 0 | Q32: =((0.45/1000*7860*30200)+(0.4/1000*7860*22000)+(15/1000*48*50000))*1 -> 211985.4
B33: DOOR | P33: 1520T(NA06) | Q33: =Q32/'AHU IU1'!$H$7 -> 12.113451 | R33: =((('AHU IU1'!$D$2-40)/1000*('AHU IU1'!$E$2-40)/1000)*2+((('AHU IU1'!$D$2-40)/1000*('AHU IU1'!$F$2-40)/1000)*2)+(('AHU IU1'!$E$2-40)/1000*('AHU IU1'!$F$2-40)/1000)*2) -> 26.2098 | X33: =1.8*0.4 -> 0.72 | Y33: RAG/FAG
B34: 22 | C34: Access Door | D34: PCS | E34: 1 | F34: USD | G34: 80 | H34: =IF(F34="Rp",1/$H$7,1) -> 1 | I34: 1.5 | J34: 1 | K34: =+G34*H34*I34*J34 -> 120 | L34: =+E34*K34 -> 120 | M34: =L34*16500 -> 1980000 | Q34: =((0.45/1000*7860*30200)+(0.4/1000*7860*22000)+(15/1000*48*50000))*1 -> 211985.4 | X34: =715000/X33 -> 993055.56 | Y34: per m2
B35: 23 | C35: MFG 125 DS50 | D35: PCS | E35: 0 | F35: RP | G35: 100000 | H35: =IF(F35="Rp",1/$H$7,1) -> 5.7142857e-05 | I35: 1 | J35: 1 | K35: =+G35*H35*I35*J35 -> 5.7142857 | L35: =+E35*K35 -> 0 | M35: =L35*16500 -> 0 | P35: 1520T(NA20) | Q35: =Q34/'AHU IU1'!$H$7 -> 12.113451 | R35: =((('AHU IU1'!$D$2-40)/1000*('AHU IU1'!$E$2-40)/1000)*2+((('AHU IU1'!$D$2-40)/1000*('AHU IU1'!$F$2-40)/1000)*2)+(('AHU IU1'!$E$2-40)/1000*('AHU IU1'!$F$2-40)/1000)*2) -> 26.2098
B36: 24 | C36: MFG 134 | D36: PCS | E36: 0 | F36: RP | G36: 0 | H36: =IF(F36="Rp",1/$H$7,1) -> 5.7142857e-05 | I36: 1 | J36: 1 | K36: =+G36*H36*I36*J36 -> 0 | L36: =+E36*K36 -> 0 | M36: =L36*16500 -> 0 | Q36: =((0.45/1000*7860*30200)+(0.4/1000*7860*22000)+(15/1000*48*50000))*1 -> 211985.4
B37: FAN & MOTOR | P37: 1540T(NA06) | Q37: =Q36/'AHU IU1'!$H$7 -> 12.113451 | R37: =((('AHU IU1'!$D$2-80)/1000*('AHU IU1'!$E$2-80)/1000)*2+((('AHU IU1'!$D$2-80)/1000*('AHU IU1'!$F$2-80)/1000)*2)+(('AHU IU1'!$E$2-80)/1000*('AHU IU1'!$F$2-80)/1000)*2) -> 25.1826
A38: AT 00/00-X | B38: 25 | C38: SYD 450 R | D38: PCS | E38: 1 | F38: USD | G38: =VLOOKUP(C38,Master!J8:K283,2,0) -> 257 | H38: =IF(F38="Rp",1/$H$7,1) -> 1 | I38: 2.5 | J38: 1 | K38: =+G38*H38*I38*J38 -> 642.5 | L38: =+E38*K38 -> 642.5 | M38: =L38*16500 -> 10601250 | N38: =VLOOKUP(C38,Master!$J$8:$L$283,3,0) -> 57 | Q38: =((0.45/1000*7860*30200)+(0.4/1000*7860*22000)+(15/1000*48*50000))*1 -> 211985.4
B39: 26 | C39: Motor 7.5kW-4P | D39: PCS | E39: 1 | F39: USD | G39: =VLOOKUP(C39,Master!$F$2:$G$67,2,0) -> 362.9 | H39: =IF(F39="Rp",1/$H$7,1) -> 1 | I39: 2 | J39: 1.2 | K39: =+G39*H39*I39*J39 -> 870.96 | L39: =+E39*K39 -> 870.96 | M39: =L39*16500 -> 14370840 | P39: 1540T(NA20) | Q39: =Q38/'AHU IU1'!$H$7 -> 12.113451 | R39: =((('AHU IU1'!$D$2-80)/1000*('AHU IU1'!$E$2-80)/1000)*2+((('AHU IU1'!$D$2-80)/1000*('AHU IU1'!$F$2-80)/1000)*2)+(('AHU IU1'!$E$2-80)/1000*('AHU IU1'!$F$2-80)/1000)*2) -> 25.1826
A40: PB | B40: 27 | C40: 2SPA212 | D40: PCS | E40: 1 | F40: RP | G40: =VLOOKUP(C40,Master!$A$29:$B$436,2,0) -> 1720000 | H40: =IF(F40="Rp",1/$H$7,1) -> 5.7142857e-05 | I40: 1 | J40: 1 | K40: =+G40*H40*I40*J40 -> 98.285714 | L40: =+E40*K40 -> 98.285714 | M40: =L40*16500 -> 1621714.3 | Q40: =((0.45/1000*7860*30200)+(0.4/1000*7860*22000)+(25/1000*48*50000))*1 -> 235985.4
...

Sheet VolDamperCost2023 RA 
B1: ThermalTrue® | BB1: 11111111111111111111111111111111111111111111111111111111111111111111111111111111111111111111111111111111111111111111111111111111111111111111111111111111111111111111111111111111111111111111111111111111111111111111111111111111111111111111111111111111111111111111111111111111111111111111111111111111111111111111111111111111111111111111111111111111111111111111111111111111111111111111111111111111111111111111111111111111111111111111111111111111111111111111111111111111111111111111111111111111111111111111111111111111111111111111111111111111111111
B2: Project: | C2: Yudi
B3: Date: | C3: =TODAY() -> 46089
B4: Rp/USD: | C4: =+S43 -> 17500
B5: Material CostList Volume Damper PS125
B6: PickList | C6: P/Ninternal | D6: Parts List : Frame | E6: UW | F6: UC(Rp) | G6: FOB | H6: LF | I6: Fx | J6: UC | L6: Cy | M6: FOB | N6: LF | O6: Fx | P6: UC | R6: Rp | S6: 1
B7: SPHC | C7: 0101-04-000-0 | D7: SPHC (Hot rolled) 1.0mm x 4' x 8' x7700kG/m3 | E7: 7700 | F7: =+P7 -> 18000 | L7: Rp | M7: 18000 | N7: 1 | O7: =VLOOKUP(L7,$R$6:$S$12,2,FALSE) -> 1 | P7: =+M7*N7*O7 -> 18000 | R7: USD | S7: 17500
B8: SGCC | C8: 0101-02-000-0 | D8: SGCC (GI) 1.0mm x 4' x 8' x 8030kG/m3 | E8: 8030 | F8: =+P8 -> 30000 | L8: Rp | M8: 30000 | N8: 1 | O8: =VLOOKUP(L8,$R$6:$S$12,2,FALSE) -> 1 | P8: =+M8*N8*O8 -> 30000 | R8: Euro | S8: 16079.99
B9: SUS304 | C9: 0101-05-000-0 | D9: Stainless Stl (SUS304) 1.0mm x 4' x 8' x 7800kG/m3 | E9: 7800 | F9: =+P9 -> 55000 | L9: Rp | M9: 55000 | N9: 1 | O9: =VLOOKUP(L9,$R$6:$S$12,2,FALSE) -> 1 | P9: =+M9*N9*O9 -> 55000 | R9: RM | S9: 3429.69
B10: SUS36L | C10: 0101-06-000-0 | D10: Stainless Stl (SUS316L) 1.0mm x 4' x 8' x 8000kG/m3 | E10: 8000 | F10: =+P10 -> 55000 | L10: Rp | M10: 55000 | N10: 1 | O10: =VLOOKUP(L10,$R$6:$S$12,2,FALSE) -> 1 | P10: =+M10*N10*O10 -> 55000 | R10: Rmb | S10: 2192.36
B11: Al6065 | C11: 0101-07-000-0 | D11: Aluminium 6065 1.0mm x 4' x 8' x 2720kG/m3 | E11: 2720 | F11: =+P11 -> 83085 | L11: Rp | M11: 83085 | N11: 1 | O11: =VLOOKUP(L11,$R$6:$S$12,2,FALSE) -> 1 | P11: =+M11*N11*O11 -> 83085 | R11: S$ | S11: 11262.76
B12: ET6065 | C12: 0102-00-000-0 | D12: Aluminium Extrusion 6065-T5, NA | E12: 1 | F12: =+P12 -> 78000 | L12: Rp | M12: 78000 | N12: 1 | O12: =VLOOKUP(L12,$R$6:$S$12,2,FALSE) -> 1 | P12: =+M12*N12*O12 -> 78000 | R12: Rs | S12: 183.43
B13: SH5037 | D13: Damper Frame : Horizontal, T/B Profile -34.4T x 125W | E13: 1.032 | F13: =+P13 -> 86114.208 | G13: =3.2*E13 -> 3.3024 | H13: 1.5 | I13: =+S$7 -> 17500 | J13: =+G13*H13*I13 -> 86688 | L13: Rp | M13: =+E13*(((10430500/25)/6)*1.2) -> 86114.208 | N13: 1 | O13: =VLOOKUP(L13,$R$6:$S$12,2,FALSE) -> 1 | P13: =+M13*N13*O13 -> 86114.208
B14: SH5038 | D14: Damper Frame : Vertical, L/R Profile - 34.4T x 125W | E14: 1.4 | F14: =+P14 -> 109200 | G14: =3.2*E14 -> 4.48 | H14: 1.5 | I14: =+S$7 -> 17500 | J14: =+G14*H14*I14 -> 117600 | L14: Rp | M14: =+E14*M$12 -> 109200 | N14: 1 | O14: =VLOOKUP(L14,$R$6:$S$12,2,FALSE) -> 1 | P14: =+M14*N14*O14 -> 109200
B15: SH5039 | D15: Damper Frame : Vertical, Center Profile - 34.4T x 125W | E15: 1.759 | F15: =+P15 -> 214624.38 | G15: =3.2*E15 -> 5.6288 | H15: 1.5 | I15: =+S$7 -> 17500 | J15: =+G15*H15*I15 -> 147756 | L15: Rp | M15: =+E15*((14641800/20)/6) -> 214624.38 | N15: 1 | O15: =VLOOKUP(L15,$R$6:$S$12,2,FALSE) -> 1 | P15: =+M15*N15*O15 -> 214624.38
B16: SH5040 | D16: Damper, Leaf : Flat Blade Profile - 15.7T x 108W | E16: 0.85 | F16: =+P16 -> 69353.625 | G16: =3.2*E16 -> 2.72 | H16: 1.5 | I16: =+S$7 -> 17500 | J16: =+G16*H16*I16 -> 71400 | L16: Rp | M16: =+E16*(((17950350/55)/6)*1.5) -> 69353.625 | N16: 1 | O16: =VLOOKUP(L16,$R$6:$S$12,2,FALSE) -> 1 | P16: =+M16*N16*O16 -> 69353.625
B17: GA100 | D17: Damper, Gasket : 200m/roll (密封胶条） | E17: =7.47/200 -> 0.03735 | F17: =+P17 -> 2454.75 | G17: 0.1 | H17: 1.5 | I17: =+S$7 -> 17500 | J17: =+G17*H17*I17 -> 2625 | L17: USD | M17: =((1636500/5)/200)/17500 -> 0.093514286 | N17: 1.5 | O17: =VLOOKUP(L17,$R$6:$S$12,2,FALSE) -> 17500 | P17: =+M17*N17*O17 -> 2454.75
B18: AC004 | D18: Damper, Gear Housing Set : PA (齿轮） | E18: 0.12 | F18: =+P18 -> 20355 | G18: 0.8 | H18: 1.5 | I18: =+S$7 -> 17500 | J18: =+G18*H18*I18 -> 21000 | L18: USD | M18: =(16284000/1200)/17500 -> 0.77542857 | N18: 1.5 | O18: =VLOOKUP(L18,$R$6:$S$12,2,FALSE) -> 17500 | P18: =+M18*N18*O18 -> 20355
B19: S60 | D19: - Spacer | E19: 0.005
B20: CPS931 | D20: - Gear Cover | E20: 0.06
B21: CPS932 | D21: - Gear | E21: 0.04
B22: CPS933 | D22: - Blade/Gear Nylon Bush | E22: 0.005
B23: CPS934 | D23: - Blade/Gear Nylon Plug | E23: 0.01
B24: AC003 | D24: Damper, Handle : (铝执手) | E24: 0.37 | F24: =+P24 -> 117990 | G24: 4.4 | H24: 1.5 | I24: =+S$7 -> 17500 | J24: =+G24*H24*I24 -> 115500 | L24: USD | M24: =(11799000/150)/17500 -> 4.4948571 | N24: 1.5 | O24: =VLOOKUP(L24,$R$6:$S$12,2,FALSE) -> 17500 | P24: =+M24*N24*O24 -> 117990
B25: AC003.1 | D25: - Handle Base | E25: 0.13
B26: AC003.2 | D26: - Handle | E26: 0.11
B27: AC003.3 | D27: - Handle Turning Plug | E27: 0.07
B28: AC003.4 | D28: - Handle Lock Nut | E28: 0.05
B29: PMS80 | D29: Damper, Actuator Base : 90W x 150L | E29: 0.715 | F29: =+P29 -> 94500 | L29: USD | M29: 3.6 | N29: 1.5 | O29: =VLOOKUP(L29,$R$6:$S$12,2,FALSE) -> 17500 | P29: =+M29*N29*O29 -> 94500
B30: WN06 | C30: 0712-01-002-4 | D30: Nut, Wing M06 | E30: 0.008 | F30: =+P30 -> 4000 | L30: Rp | M30: 4000 | N30: 1 | O30: =VLOOKUP(L30,$R$6:$S$12,2,FALSE) -> 1 | P30: =+M30*N30*O30 -> 4000
B31: HB0620 | C31: 0701-03-003-4 | D31: Bolt, Hex M06 x 20 | E31: 0.002 | F31: =+P31 -> 1890 | L31: Rp | M31: 1890 | N31: 1 | O31: =VLOOKUP(L31,$R$6:$S$12,2,FALSE) -> 1 | P31: =+M31*N31*O31 -> 1890
B32: HB0820 | C32: 0701-04-003-4 | D32: Bolt, Hex M08 x 20 | E32: 0.011 | F32: =+P32 -> 3180 | L32: Rp | M32: 3180 | N32: 1 | O32: =VLOOKUP(L32,$R$6:$S$12,2,FALSE) -> 1 | P32: =+M32*N32*O32 -> 3180
B33: RB10 | D33: Ring Bush 10mm | E33: 0.005 | F33: =+P33 -> 100 | L33: Rp | M33: 100 | N33: 1 | O33: =VLOOKUP(L33,$R$6:$S$12,2,FALSE) -> 1 | P33: =+M33*N33*O33 -> 100
B34: SR05 | D34: Snap Ring #5 | E34: 0.002 | F34: =+P34 -> 100 | L34: Rp | M34: 100 | N34: 1 | O34: =VLOOKUP(L34,$R$6:$S$12,2,FALSE) -> 1 | P34: =+M34*N34*O34 -> 100
B35: 2Nm | D35: Actuator 2Nm, 70sec : 0.5m2 FA | E35: 0.5 | L35: USD
B36: 5Nm | D36: Actuator 5Nm, 90sec : 1.0m2 FA | E36: 0.5 | L36: USD
B37: 10Nm | D37: Actuator 10Nm, 100sec : 2.0m2 FA | E37: 0.5 | L37: USD
B38: 20Nm | D38: Actuator 20Nm, 120sec : 4.0m2 FA | E38: 0.9 | L38: USD
B39: 30Nm | D39: Actuator 30Nm, 150sec : 6.0m2 FA | E39: 1.4 | L39: USD
B40: 40Nm | D40: Actuator 40Nm, 180sec : 8.0m2 FA | E40: 1.4 | L40: USD
...

Sheet VolDamperCost2023 FA 
B1: ThermalTrue® | BB1: 11111111111111111111111111111111111111111111111111111111111111111111111111111111111111111111111111111111111111111111111111111111111111111111111111111111111111111111111111111111111111111111111111111111111111111111111111111111111111111111111111111111111111111111111111111111111111111111111111111111111111111111111111111111111111111111111111111111111111111111111111111111111111111111111111111111111111111111111111111111111111111111111111111111111111111111111111111111111111111111111111111111111111111111111111111111111111111111111111111111111111
B2: Project: | C2: Yudi
B3: Date: | C3: =TODAY() -> 46089
B4: Rp/USD: | C4: =+S43 -> 17500
B5: Material CostList Volume Damper PS125
B6: PickList | C6: P/Ninternal | D6: Parts List : Frame | E6: UW | F6: UC(Rp) | G6: FOB | H6: LF | I6: Fx | J6: UC | L6: Cy | M6: FOB | N6: LF | O6: Fx | P6: UC | R6: Rp | S6: 1
B7: SPHC | C7: 0101-04-000-0 | D7: SPHC (Hot rolled) 1.0mm x 4' x 8' x7700kG/m3 | E7: 7700 | F7: =+P7 -> 18000 | L7: Rp | M7: 18000 | N7: 1 | O7: =VLOOKUP(L7,$R$6:$S$12,2,FALSE) -> 1 | P7: =+M7*N7*O7 -> 18000 | R7: USD | S7: 17500
B8: SGCC | C8: 0101-02-000-0 | D8: SGCC (GI) 1.0mm x 4' x 8' x 8030kG/m3 | E8: 8030 | F8: =+P8 -> 30000 | L8: Rp | M8: 30000 | N8: 1 | O8: =VLOOKUP(L8,$R$6:$S$12,2,FALSE) -> 1 | P8: =+M8*N8*O8 -> 30000 | R8: Euro | S8: 16079.99
B9: SUS304 | C9: 0101-05-000-0 | D9: Stainless Stl (SUS304) 1.0mm x 4' x 8' x 7800kG/m3 | E9: 7800 | F9: =+P9 -> 55000 | L9: Rp | M9: 55000 | N9: 1 | O9: =VLOOKUP(L9,$R$6:$S$12,2,FALSE) -> 1 | P9: =+M9*N9*O9 -> 55000 | R9: RM | S9: 3429.69
B10: SUS36L | C10: 0101-06-000-0 | D10: Stainless Stl (SUS316L) 1.0mm x 4' x 8' x 8000kG/m3 | E10: 8000 | F10: =+P10 -> 55000 | L10: Rp | M10: 55000 | N10: 1 | O10: =VLOOKUP(L10,$R$6:$S$12,2,FALSE) -> 1 | P10: =+M10*N10*O10 -> 55000 | R10: Rmb | S10: 2192.36
B11: Al6065 | C11: 0101-07-000-0 | D11: Aluminium 6065 1.0mm x 4' x 8' x 2720kG/m3 | E11: 2720 | F11: =+P11 -> 83085 | L11: Rp | M11: 83085 | N11: 1 | O11: =VLOOKUP(L11,$R$6:$S$12,2,FALSE) -> 1 | P11: =+M11*N11*O11 -> 83085 | R11: S$ | S11: 11262.76
B12: ET6065 | C12: 0102-00-000-0 | D12: Aluminium Extrusion 6065-T5, NA | E12: 1 | F12: =+P12 -> 78000 | L12: Rp | M12: 78000 | N12: 1 | O12: =VLOOKUP(L12,$R$6:$S$12,2,FALSE) -> 1 | P12: =+M12*N12*O12 -> 78000 | R12: Rs | S12: 183.43
B13: SH5037 | D13: Damper Frame : Horizontal, T/B Profile -34.4T x 125W | E13: 1.032 | F13: =+P13 -> 86114.208 | G13: =3.2*E13 -> 3.3024 | H13: 1.5 | I13: =+S$7 -> 17500 | J13: =+G13*H13*I13 -> 86688 | L13: Rp | M13: =+E13*(((10430500/25)/6)*1.2) -> 86114.208 | N13: 1 | O13: =VLOOKUP(L13,$R$6:$S$12,2,FALSE) -> 1 | P13: =+M13*N13*O13 -> 86114.208
B14: SH5038 | D14: Damper Frame : Vertical, L/R Profile - 34.4T x 125W | E14: 1.4 | F14: =+P14 -> 109200 | G14: =3.2*E14 -> 4.48 | H14: 1.5 | I14: =+S$7 -> 17500 | J14: =+G14*H14*I14 -> 117600 | L14: Rp | M14: =+E14*M$12 -> 109200 | N14: 1 | O14: =VLOOKUP(L14,$R$6:$S$12,2,FALSE) -> 1 | P14: =+M14*N14*O14 -> 109200
B15: SH5039 | D15: Damper Frame : Vertical, Center Profile - 34.4T x 125W | E15: 1.759 | F15: =+P15 -> 214624.38 | G15: =3.2*E15 -> 5.6288 | H15: 1.5 | I15: =+S$7 -> 17500 | J15: =+G15*H15*I15 -> 147756 | L15: Rp | M15: =+E15*((14641800/20)/6) -> 214624.38 | N15: 1 | O15: =VLOOKUP(L15,$R$6:$S$12,2,FALSE) -> 1 | P15: =+M15*N15*O15 -> 214624.38
B16: SH5040 | D16: Damper, Leaf : Flat Blade Profile - 15.7T x 108W | E16: 0.85 | F16: =+P16 -> 69353.625 | G16: =3.2*E16 -> 2.72 | H16: 1.5 | I16: =+S$7 -> 17500 | J16: =+G16*H16*I16 -> 71400 | L16: Rp | M16: =+E16*(((17950350/55)/6)*1.5) -> 69353.625 | N16: 1 | O16: =VLOOKUP(L16,$R$6:$S$12,2,FALSE) -> 1 | P16: =+M16*N16*O16 -> 69353.625
B17: GA100 | D17: Damper, Gasket : 200m/roll (密封胶条） | E17: =7.47/200 -> 0.03735 | F17: =+P17 -> 2454.75 | G17: 0.1 | H17: 1.5 | I17: =+S$7 -> 17500 | J17: =+G17*H17*I17 -> 2625 | L17: USD | M17: =((1636500/5)/200)/17500 -> 0.093514286 | N17: 1.5 | O17: =VLOOKUP(L17,$R$6:$S$12,2,FALSE) -> 17500 | P17: =+M17*N17*O17 -> 2454.75
B18: AC004 | D18: Damper, Gear Housing Set : PA (齿轮） | E18: 0.12 | F18: =+P18 -> 20355 | G18: 0.8 | H18: 1.5 | I18: =+S$7 -> 17500 | J18: =+G18*H18*I18 -> 21000 | L18: USD | M18: =(16284000/1200)/17500 -> 0.77542857 | N18: 1.5 | O18: =VLOOKUP(L18,$R$6:$S$12,2,FALSE) -> 17500 | P18: =+M18*N18*O18 -> 20355
B19: S60 | D19: - Spacer | E19: 0.005
B20: CPS931 | D20: - Gear Cover | E20: 0.06
B21: CPS932 | D21: - Gear | E21: 0.04
B22: CPS933 | D22: - Blade/Gear Nylon Bush | E22: 0.005
B23: CPS934 | D23: - Blade/Gear Nylon Plug | E23: 0.01
B24: AC003 | D24: Damper, Handle : (铝执手) | E24: 0.37 | F24: =+P24 -> 117990 | G24: 4.4 | H24: 1.5 | I24: =+S$7 -> 17500 | J24: =+G24*H24*I24 -> 115500 | L24: USD | M24: =(11799000/150)/17500 -> 4.4948571 | N24: 1.5 | O24: =VLOOKUP(L24,$R$6:$S$12,2,FALSE) -> 17500 | P24: =+M24*N24*O24 -> 117990
B25: AC003.1 | D25: - Handle Base | E25: 0.13
B26: AC003.2 | D26: - Handle | E26: 0.11
B27: AC003.3 | D27: - Handle Turning Plug | E27: 0.07
B28: AC003.4 | D28: - Handle Lock Nut | E28: 0.05
B29: PMS80 | D29: Damper, Actuator Base : 90W x 150L | E29: 0.715 | F29: =+P29 -> 94500 | L29: USD | M29: 3.6 | N29: 1.5 | O29: =VLOOKUP(L29,$R$6:$S$12,2,FALSE) -> 17500 | P29: =+M29*N29*O29 -> 94500
B30: WN06 | C30: 0712-01-002-4 | D30: Nut, Wing M06 | E30: 0.008 | F30: =+P30 -> 4000 | L30: Rp | M30: 4000 | N30: 1 | O30: =VLOOKUP(L30,$R$6:$S$12,2,FALSE) -> 1 | P30: =+M30*N30*O30 -> 4000
B31: HB0620 | C31: 0701-03-003-4 | D31: Bolt, Hex M06 x 20 | E31: 0.002 | F31: =+P31 -> 1890 | L31: Rp | M31: 1890 | N31: 1 | O31: =VLOOKUP(L31,$R$6:$S$12,2,FALSE) -> 1 | P31: =+M31*N31*O31 -> 1890
B32: HB0820 | C32: 0701-04-003-4 | D32: Bolt, Hex M08 x 20 | E32: 0.011 | F32: =+P32 -> 3180 | L32: Rp | M32: 3180 | N32: 1 | O32: =VLOOKUP(L32,$R$6:$S$12,2,FALSE) -> 1 | P32: =+M32*N32*O32 -> 3180
B33: RB10 | D33: Ring Bush 10mm | E33: 0.005 | F33: =+P33 -> 100 | L33: Rp | M33: 100 | N33: 1 | O33: =VLOOKUP(L33,$R$6:$S$12,2,FALSE) -> 1 | P33: =+M33*N33*O33 -> 100
B34: SR05 | D34: Snap Ring #5 | E34: 0.002 | F34: =+P34 -> 100 | L34: Rp | M34: 100 | N34: 1 | O34: =VLOOKUP(L34,$R$6:$S$12,2,FALSE) -> 1 | P34: =+M34*N34*O34 -> 100
B35: 2Nm | D35: Actuator 2Nm, 70sec : 0.5m2 FA | E35: 0.5 | L35: USD
B36: 5Nm | D36: Actuator 5Nm, 90sec : 1.0m2 FA | E36: 0.5 | L36: USD
B37: 10Nm | D37: Actuator 10Nm, 100sec : 2.0m2 FA | E37: 0.5 | L37: USD
B38: 20Nm | D38: Actuator 20Nm, 120sec : 4.0m2 FA | E38: 0.9 | L38: USD
B39: 30Nm | D39: Actuator 30Nm, 150sec : 6.0m2 FA | E39: 1.4 | L39: USD
B40: 40Nm | D40: Actuator 40Nm, 180sec : 8.0m2 FA | E40: 1.4 | L40: USD
...

Sheet drainpan
A1: x | B1: xx
D2: D | E2: 1000 | F2: Ømm | G2: mmT | H2: mmL | I2: mmW | J2: kg/m3 | K2: N(pc) | L2: Qty/Unit | M2: Unit/Set | N2: WF | O2: Rp/USD | P2: 17500 | Q2: U/P | R2: LF | S2: Total
D3: W | E3: 500
D4: H | E4: 50
B5: Drain Pan 1 | D5: Matl | E5: Uom | O5: Qty/Set | P5: Fx | S5: USD
C6: Structure | W6: 304
